<!-- standalone multisense head used for capturing data and perception tests-->
<sdf version='1.3'>



  <model name='atlas'>
    <static>0</static>

    <joint name='world_joint' type='revolute'>
      <child>head</child>
      <parent>world</parent>
      <pose>0.0 0.0 2</pose>
      <axis>
        <limit>
          <lower>0.000000</lower>
          <upper>0.000000</upper>
        </limit>
        <dynamics>
          <damping>0.000000</damping>
        </dynamics>
        <xyz>0.000000 0.000000 1.000000</xyz>
      </axis>
    </joint>

    <link name='head'>
      <gravity>1</gravity>
      <pose>0.000000 0.000000 0.000000 0.000000 0.000000 0.000000</pose>
      <inertial>
        <pose>-0.066172 0.000029 0.024068 0.000000 0.000000 0.000000</pose>
        <mass>1.619900</mass>
        <inertia>
          <ixx>0.006215</ixx>
          <ixy>-0.000002</ixy>
          <ixz>-0.000893</ixz>
          <iyy>0.006119</iyy>
          <iyz>-0.000001</iyz>
          <izz>0.005769</izz>
        </inertia>
      </inertial>
      <collision name='head_collision'>
        <pose>-0.044600 0.000000 0.088000 0.000000 0.000000 1.570790</pose>
        <geometry>
          <mesh>
            <scale>1.000000 1.000000 1.000000</scale>
            <uri>model://multisense_sl/meshes/base_link.STL</uri>
          </mesh>
        </geometry>
      </collision>
      <visual name='head_vis'>
        <pose>-0.044600 0.000000 0.088000 0.000000 0.000000 1.570790</pose>
        <geometry>
          <mesh>
            <scale>1.000000 1.000000 1.000000</scale>
            <uri>model://multisense_sl/meshes/base_link.STL</uri>
          </mesh>
        </geometry>
      </visual>
      <velocity_decay>
        <linear>0.000000</linear>
        <angular>0.000000</angular>
      </velocity_decay>
      <sensor name='left_camera_sensor' type='camera'>
        <visualize>0</visualize>
        <update_rate>15.000000</update_rate>
        <camera name='__default__'>
          <horizontal_fov>1.396263</horizontal_fov>
          <image>
            <width>2048</width>
            <height>1088</height>
            <format>R8G8B8</format>
          </image>
          <clip>
            <near>0.020000</near>
            <far>100.000000</far>
          </clip>
        </camera>
        <plugin name='left_camera_controller' filename='libgazebo_ros_camera.so'>
          <alwaysOn>1</alwaysOn>
          <updateRate>15.0</updateRate>
          <cameraName>multisense_sl/left</cameraName>
          <imageTopicName>image_raw</imageTopicName>
          <cameraInfoTopicName>camera_info</cameraInfoTopicName>
          <frameName>left_camera_optical_frame</frameName>
          <hackBaseline>0.0</hackBaseline>
          <distortionK1>0.0</distortionK1>
          <distortionK2>0.0</distortionK2>
          <distortionK3>0.0</distortionK3>
          <distortionT1>0.0</distortionT1>
          <distortionT2>0.0</distortionT2>
        </plugin>
        <pose>0.000000 0.035000 -0.002000 0.000000 0.000000 0.000000</pose>
      </sensor>
      <velocity_decay>
        <linear>0.000000</linear>
        <angular>0.000000</angular>
      </velocity_decay>
      <self_collide>0</self_collide>
      <sensor name='right_camera_sensor' type='camera'>
        <visualize>0</visualize>
        <update_rate>15.000000</update_rate>
        <camera name='__default__'>
          <horizontal_fov>1.396263</horizontal_fov>
          <image>
            <width>2048</width>
            <height>1088</height>
            <format>R8G8B8</format>
          </image>
          <clip>
            <near>0.020000</near>
            <far>100.000000</far>
          </clip>
        </camera>
        <plugin name='right_camera_controller' filename='libgazebo_ros_camera.so'>
          <alwaysOn>1</alwaysOn>
          <updateRate>15.0</updateRate>
          <cameraName>multisense_sl/right</cameraName>
          <imageTopicName>image_raw</imageTopicName>
          <cameraInfoTopicName>camera_info</cameraInfoTopicName>
          <frameName>left_camera_optical_frame</frameName>
          <hackBaseline>0.07</hackBaseline>
          <distortionK1>0.0</distortionK1>
          <distortionK2>0.0</distortionK2>
          <distortionK3>0.0</distortionK3>
          <distortionT1>0.0</distortionT1>
          <distortionT2>0.0</distortionT2>
        </plugin>
        <pose>0.000000 -0.035000 -0.002000 0.000000 0.000000 0.000000</pose>
      </sensor>
    </link>
    <link name='hokuyo_link'>
      <gravity>1</gravity>
      <pose>-0.044600 0.000000 0.088000 0.000000 0.000000 0.000000</pose>
      <inertial>
        <pose>0.015025 0.000348 -0.001348 0.000000 0.000000 0.000000</pose>
        <mass>0.067664</mass>
        <inertia>
          <ixx>0.000049</ixx>
          <ixy>0.000000</ixy>
          <ixz>0.000007</ixz>
          <iyy>0.000064</iyy>
          <iyz>-0.000000</iyz>
          <izz>0.000061</izz>
        </inertia>
      </inertial>
      <collision name='hokuyo_link_collision'>
        <pose>0.000000 0.000000 0.000000 1.570800 -0.000000 1.570800</pose>
        <geometry>
          <mesh>
            <scale>1.000000 1.000000 1.000000</scale>
            <uri>model://multisense_sl/meshes/hokuyo_link.STL</uri>
          </mesh>
        </geometry>
      </collision>
      <visual name='hokuyo_link_vis'>
        <pose>0.000000 0.000000 0.000000 1.570800 -0.000000 1.570800</pose>
        <geometry>
          <mesh>
            <scale>1.000000 1.000000 1.000000</scale>
            <uri>model://multisense_sl/meshes/hokuyo_link.STL</uri>
          </mesh>
        </geometry>
      </visual>
      <velocity_decay>
        <linear>0.000000</linear>
        <angular>0.000000</angular>
      </velocity_decay>
      <self_collide>0</self_collide>
      <sensor name='head_hokuyo_sensor' type='ray'>
        <visualize>0</visualize>
        <update_rate>40.000000</update_rate>
        <ray>
          <scan>
            <horizontal>
              <samples>720</samples>
              <resolution>1.000000</resolution>
              <min_angle>-1.570796</min_angle>
              <max_angle>1.570796</max_angle>
            </horizontal>
          </scan>
          <range>
            <min>0.100000</min>
            <max>30.000000</max>
            <resolution>0.010000</resolution>
          </range>
        </ray>
        <plugin name='gazebo_ros_head_hokuyo_controller' filename='libgazebo_ros_laser.so'>
          <gaussianNoise>0.005</gaussianNoise>
          <alwaysOn>1</alwaysOn>
          <updateRate>40</updateRate>
          <topicName>/scan</topicName>
          <frameName>head_hokuyo</frameName>
        </plugin>
        <pose>0.030000 0.000000 0.015000 0.000000 0.000000 0.000000</pose>
      </sensor>
    </link>
    <joint name='hokuyo_joint' type='revolute'>
      <child>hokuyo_link</child>
      <parent>head</parent>
      <axis>
        <xyz>1.000000 0.000000 0.000000</xyz>
        <limit>
          <lower>-10000000000000000.000000</lower>
          <upper>10000000000000000.000000</upper>
        </limit>
        <dynamics>
          <damping>0.010000</damping>
        </dynamics>
      </axis>
    </joint>
    <plugin name='multisense_plugin' filename='libMultiSenseSLPlugin.so'/>
    <plugin name='gazebo_ros_controller_manager' filename='libgazebo_ros_controller_manager.so'>
      <alwaysOn>1</alwaysOn>
      <updateRate>1000.0</updateRate>
    </plugin>
    <plugin name='gazebo_ros_p3d' filename='libgazebo_ros_p3d.so'>
      <bodyName>head</bodyName>
      <topicName>/head_pose</topicName>
      <alwaysOn>1</alwaysOn>
      <updateRate>100.0</updateRate>
    </plugin>
  </model>
</sdf>
